Workbook

Sheet Test Cases
A1: S.No | B1: Module | C1: Spec File | D1: Line | E1: Suite (describe) | F1: Test ID | G1: Test Title | H1: Existing Tags | I1: Regression (Y/N) | J1: Smoke (Y/N) | K1: Priority | L1: New Tag(s) | M1: Remarks
A2: 1 | B2: root | C2: Pricing_general_Create.spec.js | D2: 21 | E2: Pricing_general_Create | F2: TC01 | G2: TC01 - Create a General price list with Overall Markup
A3: 2 | B3: root | C3: Pricing_general_Create.spec.js | D3: 33 | E3: Pricing_general_Create | F3: TC02 | G3: TC02 - Create a General price list with Overall Markdown
A4: 3 | B4: root | C4: Pricing_general_Create.spec.js | D4: 45 | E4: Pricing_general_Create | F4: TC03 | G4: TC03 - Create a General price list with Item Specific pricing
A5: 4 | B5: root | C5: Pricing_general_Create.spec.js | D5: 57 | E5: Pricing_general_Create | F5: TC04 | G5: TC04 - Create a General price list with Item Specific pricing by auto calculation
A6: 5 | B6: root | C6: Pricing_general_Create.spec.js | D6: 69 | E6: Pricing_general_Create | F6: TC05 | G6: TC05 - Create a Category Wise price list with Overall Markup
A7: 6 | B7: root | C7: Pricing_general_Create.spec.js | D7: 82 | E7: Pricing_general_Create | F7: TC06 | G7: TC06 - Create a Category Wise price list with Overall Markdown
A8: 7 | B8: root | C8: Pricing_general_Create.spec.js | D8: 94 | E8: Pricing_general_Create | F8: TC07 | G8: TC07 - Create a Category Wise price list with Item Specific pricing
A9: 8 | B9: root | C9: Pricing_general_Create.spec.js | D9: 106 | E9: Pricing_general_Create | F9: TC08 | G9: TC08 - Create a Category Wise price list with Item Specific pricing by auto calculation
A10: 9 | B10: root | C10: Pricing_general_Create.spec.js | D10: 118 | E10: Pricing_general_Create | F10: TC09 | G10: TC09 - Create a Profile Wise price list with Overall Markup
A11: 10 | B11: root | C11: Pricing_general_Create.spec.js | D11: 131 | E11: Pricing_general_Create | F11: TC10 | G11: TC10 - Create a Profile Wise price list with Overall Markdown
A12: 11 | B12: root | C12: Pricing_general_Create.spec.js | D12: 143 | E12: Pricing_general_Create | F12: TC11 | G12: TC11 - Create a Profile Wise price list with Item Specific pricing
A13: 12 | B13: root | C13: Pricing_general_Create.spec.js | D13: 155 | E13: Pricing_general_Create | F13: TC12 | G13: TC12 - Create a Profile Wise price list with Item Specific pricing by auto calculation
... A32: 31 | B32: root | C32: Vendor_Create.spec.js | D32: 46 | E32: Vendor_Create | F32: TC04 | G32: TC04 - Edit the Business Vendor with GST
A33: 32 | B33: _tools | C33: _tools/pricing-cleanup.spec.js | D33: 9 | G33: cleanup: no active ZZ price lists / offers
A34: 33 | B34: finance | C34: finance/01_ChequeTracker.spec.js | D34: 51 | E34: Cheque Tracker | F34: CT TC-UI-01 / 04 / 05 / 06 / 07 / 08 / 09 / 13 / 14 / 15 / 16 / 17 | G34: CT TC-UI-01 / 04 / 05 / 06 / 07 / 08 / 09 / 13 / 14 / 15 / 16 / 17 - Tabs with counts; columns per tab; Search, dates, Export, Move to (Revert on Cleared); ⋮ on rows | H34: @cheque @finance
A35: 34 | B35: finance | C35: finance/01_ChequeTracker.spec.js | D35: 79 | E35: Cheque Tracker | F35: CT TC-UI-10 / 11 | G35: CT TC-UI-10 / 11 - Header checkbox selects every row; a row checkbox selects one | H35: @cheque @finance
A36: 35 | B36: finance | C36: finance/01_ChequeTracker.spec.js | D36: 93 | E36: Cheque Tracker | F36: CT TC-CIH-01 / 02 / 12 / TC-INT-01 | G36: CT TC-CIH-01 / 02 / 12 / TC-INT-01 - Cheque payment lands in Cheque In Hand with its details; invoice stays due | H36: @cheque @finance
A37: 36 | B37: finance | C37: finance/01_ChequeTracker.spec.js | D37: 105 | E37: Cheque Tracker | F37: CT TC-CIH-03 / TC-UI-03 / TC-DEP-01 / 07 / TC-INT-02 | G37: CT TC-CIH-03 / TC-UI-03 / TC-DEP-01 / 07 / TC-INT-02 - In Hand → Deposited: counts move by one, Deposited Date today, invoice still due | H37: @cheque @finance
A38: 37 | B38: finance | C38: finance/01_ChequeTracker.spec.js | D38: 117 | E38: Cheque Tracker | F38: CT TC-DEP-02 / TC-CLR-01 / 02 / 03 / 06 / TC-INT-03 / TC-RP-24 / TC-MT-09 | G38: CT TC-DEP-02 / TC-CLR-01 / 02 / 03 / 06 / TC-INT-03 / TC-RP-24 / TC-MT-09 - Deposited → Cleared: Cleared Date today; invoice Paid | H38: @cheque @finance
A39: 38 | B39: finance | C39: finance/01_ChequeTracker.spec.js | D39: 127 | E39: Cheque Tracker | F39: CT TC-CLR-04 / TC-INT-04 / TC-EC-05 | G39: CT TC-CLR-04 / TC-INT-04 / TC-EC-05 - Revert a cleared cheque: back In Hand, invoice due again | H39: @cheque @finance
A40: 39 | B40: finance | C40: finance/01_ChequeTracker.spec.js | D40: 137 | E40: Cheque Tracker | F40: CT TC-CIH-04 / TC-CAN-01 / 06 / TC-INT-05 | G40: CT TC-CIH-04 / TC-CAN-01 / 06 / TC-INT-05 - In Hand → Cancelled: Cancelled Date today, invoice due | H40: @cheque @finance
A41: 40 | B41: finance | C41: finance/01_ChequeTracker.spec.js | D41: 144 | E41: Cheque Tracker | F41: CT TC-CAN-02 / 03 / 04 / 05 | G41: CT TC-CAN-02 / 03 / 04 / 05 - Cancelled → In Hand / Deposited / Returned allowed; Cleared not offered | H41: @cheque @finance
A42: 41 | B42: finance | C42: finance/01_ChequeTracker.spec.js | D42: 160 | E42: Cheque Tracker | F42: CT TC-CIH-05 / TC-RET-01 / 02 / 13 / TC-INT-06 | G42: CT TC-CIH-05 / TC-RET-01 / 02 / 13 / TC-INT-06 - In Hand → Returned: Returned Date, Late Fee Charge filled; invoice due | H42: @cheque @finance
A43: 42 | B43: finance | C43: finance/01_ChequeTracker.spec.js | D43: 169 | E43: Cheque Tracker | F43: CT TC-CIH-06 / TC-DEP-05 / TC-MT-03 | G43: CT TC-CIH-06 / TC-DEP-05 / TC-MT-03 - Bulk: three cheques In Hand → Deposited → Cleared together | H43: @cheque @finance
A44: 43 | B44: finance | C44: finance/01_ChequeTracker.spec.js | D44: 181 | E44: Cheque Tracker | F44: CT TC-CIH-07 / TC-DEP-06 / TC-MT-05 / 07 / TC-EC-07 | G44: CT TC-CIH-07 / TC-DEP-06 / TC-MT-05 / 07 / TC-EC-07 - A future-dated cheque cannot be moved; today's can (mixed bulk moves only the dated one) | H44: @cheque @finance
A45: 44 | B45: finance | C45: finance/01_ChequeTracker.spec.js | D45: 190 | E45: Cheque Tracker | F45: CT TC-CIH-08 / TC-MT-06 | G45: CT TC-CIH-08 / TC-MT-06 - Move to with nothing selected does nothing (or asks to select) | H45: @cheque @finance
... A55: 54 | B55: finance | C55: finance/01_ChequeTracker.spec.js | D55: 325 | E55: Cheque Tracker | F55: CT TC-RET-11 / TC-EC-04 | G55: CT TC-RET-11 / TC-EC-04 - A returned cheque without a collected fee can be deleted (⋮ Delete) | H55: @cheque @finance
A56: 55 | B56: finance | C56: finance/01_ChequeTracker.spec.js | D56: 346 | E56: Cheque Tracker | F56: CT TC-UI-02 | G56: CT TC-UI-02 - Tab counts = records (Counts are checked as they change (CT TC-CIH-03); other users add cheques to the same org.)
A57: 56 | B57: finance | C57: finance/01_ChequeTracker.spec.js | D57: 346 | E57: Cheque Tracker | F57: CT TC-UI-12 | G57: CT TC-UI-12 - Responsive layout (Visual design check.)
A58: 57 | B58: finance | C58: finance/01_ChequeTracker.spec.js | D58: 346 | E58: Cheque Tracker | F58: CT TC-CIH-10 / 11 | G58: CT TC-CIH-10 / 11 - Upload attachment (image / invalid file) (Needs image fixtures for the upload dialog.)
A59: 58 | B59: finance | C59: finance/01_ChequeTracker.spec.js | D59: 346 | E59: Cheque Tracker | F59: CT TC-CLR-05 | G59: CT TC-CLR-05 - Bulk revert (Same Revert action as CT TC-CLR-04, run per cheque.)
A60: 59 | B60: finance | C60: finance/01_ChequeTracker.spec.js | D60: 346 | E60: Cheque Tracker | F60: CT TC-CLR-07 / TC-CAN-07 / TC-RET-14 | G60: CT TC-CLR-07 / TC-CAN-07 / TC-RET-14 - Future-dated cheque on later tabs (A future-dated cheque cannot leave In Hand (CT TC-CIH-07), so it never reaches these tabs.)
A61: 60 | B61: finance | C61: finance/01_ChequeTracker.spec.js | D61: 346 | E61: Cheque Tracker | F61: CT TC-RET-12 / TC-INT-07 / 08 / 09 | G61: CT TC-RET-12 / TC-INT-07 / 08 / 09 - Customer Transaction report entries (Customer statement checks belong to the Customer_Transaction sheet; invoice status is checked here.)
A62: 61 | B62: finance | C62: finance/01_ChequeTracker.spec.js | D62: 346 | E62: Cheque Tracker | F62: CT TC-EXP-03 | G62: CT TC-EXP-03 - Returned export columns (Export file content needs a spreadsheet parser.)
A63: 62 | B63: finance | C63: finance/01_ChequeTracker.spec.js | D63: 346 | E63: Cheque Tracker | F63: CT TC-EC-06 | G63: CT TC-EC-06 - Bulk with a cleared + an in-hand cheque (Cheques of different tabs cannot be selected together (one tab at a time).)
A64: 63 | B64: finance | C64: finance/02_ManualJournal.spec.js | D64: 43 | E64: Manual Journal | F64: MJ TC-UI-01 / 06 / 07 / 08 / TC-CJ-01 / 02 / 09 / TC-UI-02 | G64: MJ TC-UI-01 / 06 / 07 / 08 / TC-CJ-01 / 02 / 09 / TC-UI-02 - List columns and Total Count; Finance tabs; New Journal: MJN-AUTO no (read-only), today, Accrual Only default, rows and totals | H64: @finance @mj
A65: 64 | B65: finance | C65: finance/02_ManualJournal.spec.js | D65: 60 | E65: Manual Journal | F65: MJ TC-CJ-07 / TC-LI-03 | G65: MJ TC-CJ-07 / TC-LI-03 - Notes required ("Notes is Required!"); no amounts refused | H65: @finance @mj
A66: 65 | B66: finance | C66: finance/02_ManualJournal.spec.js | D66: 73 | E66: Manual Journal | F66: MJ TC-CJ-08 / 05 / TC-LI-01 / 04 / 05 / 10 / 16 / 17 / 18 / TC-WF-03 / TC-UI-03 / 04 / 05 / TC-DI-02 / 05 | G66: MJ TC-CJ-08 / 05 / TC-LI-01 / 04 / 05 / 10 / 16 / 17 / 18 / TC-WF-03 / TC-UI-03 / 04 / 05 / TC-DI-02 / 05 - Balanced ₹100 (no reference / description / contact): Open, amount 100, notes in list; view with Print / Edit / Delete | H66: @finance @mj
A67: 66 | B67: finance | C67: finance/02_ManualJournal.spec.js | D67: 92 | E67: Manual Journal | F67: MJ TC-CJ-03 / 04 / 06 | G67: MJ TC-CJ-03 / 04 / 06 - Past and future dates and an alphanumeric reference are accepted | H67: @finance @mj
...

Sheet Summary
A1: Spec File | B1: Total Tests | C1: Regression = Y | D1: Smoke = Y | E1: Not yet marked
A2: Pricing_general_Create.spec.js | B2: =COUNTIF('Test Cases'!$C$2:$C$967,A2) -> 26 | C2: =COUNTIFS('Test Cases'!$C$2:$C$967,A2,'Test Cases'!$I$2:$I$967,"Y") -> 0 | D2: =COUNTIFS('Test Cases'!$C$2:$C$967,A2,'Test Cases'!$J$2:$J$967,"Y") -> 0 | E2: =COUNTIFS('Test Cases'!$C$2:$C$967,A2,'Test Cases'!$I$2:$I$967,"") -> 26
A3: Product_item_Create.spec.js | B3: =COUNTIF('Test Cases'!$C$2:$C$967,A3) -> 1 | C3: =COUNTIFS('Test Cases'!$C$2:$C$967,A3,'Test Cases'!$I$2:$I$967,"Y") -> 0 | D3: =COUNTIFS('Test Cases'!$C$2:$C$967,A3,'Test Cases'!$J$2:$J$967,"Y") -> 0 | E3: =COUNTIFS('Test Cases'!$C$2:$C$967,A3,'Test Cases'!$I$2:$I$967,"") -> 1
A4: Vendor_Create.spec.js | B4: =COUNTIF('Test Cases'!$C$2:$C$967,A4) -> 4 | C4: =COUNTIFS('Test Cases'!$C$2:$C$967,A4,'Test Cases'!$I$2:$I$967,"Y") -> 0 | D4: =COUNTIFS('Test Cases'!$C$2:$C$967,A4,'Test Cases'!$J$2:$J$967,"Y") -> 0 | E4: =COUNTIFS('Test Cases'!$C$2:$C$967,A4,'Test Cases'!$I$2:$I$967,"") -> 4
A5: _tools/pricing-cleanup.spec.js | B5: =COUNTIF('Test Cases'!$C$2:$C$967,A5) -> 1 | C5: =COUNTIFS('Test Cases'!$C$2:$C$967,A5,'Test Cases'!$I$2:$I$967,"Y") -> 0 | D5: =COUNTIFS('Test Cases'!$C$2:$C$967,A5,'Test Cases'!$J$2:$J$967,"Y") -> 0 | E5: =COUNTIFS('Test Cases'!$C$2:$C$967,A5,'Test Cases'!$I$2:$I$967,"") -> 1
A6: finance/01_ChequeTracker.spec.js | B6: =COUNTIF('Test Cases'!$C$2:$C$967,A6) -> 30 | C6: =COUNTIFS('Test Cases'!$C$2:$C$967,A6,'Test Cases'!$I$2:$I$967,"Y") -> 0 | D6: =COUNTIFS('Test Cases'!$C$2:$C$967,A6,'Test Cases'!$J$2:$J$967,"Y") -> 0 | E6: =COUNTIFS('Test Cases'!$C$2:$C$967,A6,'Test Cases'!$I$2:$I$967,"") -> 30
A7: finance/02_ManualJournal.spec.js | B7: =COUNTIF('Test Cases'!$C$2:$C$967,A7) -> 26 | C7: =COUNTIFS('Test Cases'!$C$2:$C$967,A7,'Test Cases'!$I$2:$I$967,"Y") -> 0 | D7: =COUNTIFS('Test Cases'!$C$2:$C$967,A7,'Test Cases'!$J$2:$J$967,"Y") -> 0 | E7: =COUNTIFS('Test Cases'!$C$2:$C$967,A7,'Test Cases'!$I$2:$I$967,"") -> 26
A8: inventory/02_InventoryProduct.spec.js | B8: =COUNTIF('Test Cases'!$C$2:$C$967,A8) -> 49 | C8: =COUNTIFS('Test Cases'!$C$2:$C$967,A8,'Test Cases'!$I$2:$I$967,"Y") -> 0 | D8: =COUNTIFS('Test Cases'!$C$2:$C$967,A8,'Test Cases'!$J$2:$J$967,"Y") -> 0 | E8: =COUNTIFS('Test Cases'!$C$2:$C$967,A8,'Test Cases'!$I$2:$I$967,"") -> 49
A9: inventory/03_PriceList.spec.js | B9: =COUNTIF('Test Cases'!$C$2:$C$967,A9) -> 40 | C9: =COUNTIFS('Test Cases'!$C$2:$C$967,A9,'Test Cases'!$I$2:$I$967,"Y") -> 0 | D9: =COUNTIFS('Test Cases'!$C$2:$C$967,A9,'Test Cases'!$J$2:$J$967,"Y") -> 0 | E9: =COUNTIFS('Test Cases'!$C$2:$C$967,A9,'Test Cases'!$I$2:$I$967,"") -> 40
A10: inventory/04_Offers.spec.js | B10: =COUNTIF('Test Cases'!$C$2:$C$967,A10) -> 31 | C10: =COUNTIFS('Test Cases'!$C$2:$C$967,A10,'Test Cases'!$I$2:$I$967,"Y") -> 0 | D10: =COUNTIFS('Test Cases'!$C$2:$C$967,A10,'Test Cases'!$J$2:$J$967,"Y") -> 0 | E10: =COUNTIFS('Test Cases'!$C$2:$C$967,A10,'Test Cases'!$I$2:$I$967,"") -> 31
A11: inventory/05_VanSales.spec.js | B11: =COUNTIF('Test Cases'!$C$2:$C$967,A11) -> 11 | C11: =COUNTIFS('Test Cases'!$C$2:$C$967,A11,'Test Cases'!$I$2:$I$967,"Y") -> 0 | D11: =COUNTIFS('Test Cases'!$C$2:$C$967,A11,'Test Cases'!$J$2:$J$967,"Y") -> 0 | E11: =COUNTIFS('Test Cases'!$C$2:$C$967,A11,'Test Cases'!$I$2:$I$967,"") -> 11
A12: payment/01_CustomerPayment.spec.js | B12: =COUNTIF('Test Cases'!$C$2:$C$967,A12) -> 2 | C12: =COUNTIFS('Test Cases'!$C$2:$C$967,A12,'Test Cases'!$I$2:$I$967,"Y") -> 0 | D12: =COUNTIFS('Test Cases'!$C$2:$C$967,A12,'Test Cases'!$J$2:$J$967,"Y") -> 0 | E12: =COUNTIFS('Test Cases'!$C$2:$C$967,A12,'Test Cases'!$I$2:$I$967,"") -> 2
A13: purchase/01_PurchaseFlow.spec.js | B13: =COUNTIF('Test Cases'!$C$2:$C$967,A13) -> 14 | C13: =COUNTIFS('Test Cases'!$C$2:$C$967,A13,'Test Cases'!$I$2:$I$967,"Y") -> 0 | D13: =COUNTIFS('Test Cases'!$C$2:$C$967,A13,'Test Cases'!$J$2:$J$967,"Y") -> 0 | E13: =COUNTIFS('Test Cases'!$C$2:$C$967,A13,'Test Cases'!$I$2:$I$967,"") -> 14
... A24: unit_flows/Sales_Unit.spec.js | B24: =COUNTIF('Test Cases'!$C$2:$C$967,A24) -> 21 | C24: =COUNTIFS('Test Cases'!$C$2:$C$967,A24,'Test Cases'!$I$2:$I$967,"Y") -> 0 | D24: =COUNTIFS('Test Cases'!$C$2:$C$967,A24,'Test Cases'!$J$2:$J$967,"Y") -> 0 | E24: =COUNTIFS('Test Cases'!$C$2:$C$967,A24,'Test Cases'!$I$2:$I$967,"") -> 21
A25: TOTAL | B25: =SUM(B2:B24) -> 966 | C25: =SUM(C2:C24) -> 0 | D25: =SUM(D2:D24) -> 0 | E25: =SUM(E2:E24) -> 966
